<?xml version="1.0"?>
<robot name="ros_mani">
	<link name="base_link">
		<visual>
			<geometry>
				<mesh filename="package://ros_manipulator_project/meshes/MeshBody1.stl" scale="0.0002 0.0002 0.0002"/>
			</geometry>
			<material name="orange" />
			<origin rpy="1.57 0 0" xyz="-0.12 0.12 0" />
		</visual>
	</link>

	<link name="mani_lid_link">
		<visual>
			<geometry>
				<mesh filename="package://ros_manipulator_project/meshes/MeshBody2.stl" scale="0.0002 0.0002 0.0002"/>
			</geometry>
			<material name="white" />
			<origin rpy="1.57 0 0" xyz="-0.096 0.096 0" />
		</visual>
	</link>

	<link name="mani_arm01_link">
		<visual>
			<geometry>
				<mesh filename="package://ros_manipulator_project/meshes/MeshBody3.stl" scale="0.0002 0.0002 0.0002"/>
			</geometry>
			<material name="black" />
			<origin rpy="0 0 -0.15" xyz="-0.062 -0.042 0" />
		</visual>
	</link>

	<link name="mani_arm02_link">
		<visual>
			<geometry>
				<mesh filename="package://ros_manipulator_project/meshes/MeshBody4.stl" scale="0.0002 0.0002 0.0002"/>
			</geometry>
			<material name="red" />
			<origin rpy="0 0 0" xyz="-0.038 -0.052 -0.012" />
		</visual>
	</link>

	<link name="mani_arm03_link">
		<visual>
			<geometry>
				<mesh filename="package://ros_manipulator_project/meshes/MeshBody5.stl" scale="0.0002 0.0002 0.0002"/>
			</geometry>
			<material name="green" />
			<origin rpy="-1.57 0 0" xyz="-0.024 -0.028 0" />
		</visual>
	</link>

	<link name="mani_gripper_base_link">
		<visual>
			<geometry>
				<mesh filename="package://ros_manipulator_project/meshes/MeshBody6.stl" scale="0.0002 0.0002 0.0002"/>
			</geometry>
			<material name="orange" />
			<origin rpy="-1.57 1.57 -1.57" xyz="-0.0262 -0.028 0.025" />
		</visual>
	</link>

	<link name="mani_left_gear_link">
		<visual>
			<geometry>
				<mesh filename="package://ros_manipulator_project/meshes/MeshBody8.stl" scale="0.0002 0.0002 0.0002"/>
			</geometry>
			<material name="white" />
			<origin rpy="1.57 3.1416 -1.2" xyz="0.052 -0.054 0" />
		</visual>
	</link>

	<link name="mani_right_gear_link">
		<visual>
			<geometry>
				<mesh filename="package://ros_manipulator_project/meshes/MeshBody7.stl" scale="0.0002 0.0002 0.0002"/>
			</geometry>
			<material name="white" />
			<origin rpy="0 -1.2 0" xyz="0.018 0 -0.038" />
		</visual>
	</link>

	<link name="mani_left_gear_support_link">
		<visual>
			<geometry>
				<mesh filename="package://ros_manipulator_project/meshes/MeshBody9.stl" scale="0.0002 0.0002 0.0002"/>
			</geometry>
			<material name="black" />
			<origin rpy="1.57 3.1416 1.84" xyz="-0.01 0.005 0" />
		</visual>
	</link>

	<link name="mani_right_gear_support_link">
		<visual>
			<geometry>
				<mesh filename="package://ros_manipulator_project/meshes/MeshBody10.stl" scale="0.0002 0.0002 0.0002"/>
			</geometry>
			<material name="black" />
			<origin rpy="0 -1.2 -0.3" xyz="0.0045 0 -0.01" />
		</visual>
	</link>

	<link name="mani_left_gripper_link">
		<visual>
			<geometry>
				<mesh filename="package://ros_manipulator_project/meshes/MeshBody11.stl" scale="0.0002 0.0002 0.0002"/>
			</geometry>
			<material name="red" />
			<origin rpy="0 1.57 3.1416" xyz="0.12 0.01 0.002" />
		</visual>
	</link>

	<link name="mani_right_gripper_link">
		<visual>
			<geometry>
				<mesh filename="package://ros_manipulator_project/meshes/MeshBody12.stl" scale="0.0002 0.0002 0.0002"/>
			</geometry>
			<material name="green" />
			<origin rpy="3.1416 -1.57 3.1416" xyz="0.1213 -0.01 -0.015" />
		</visual>
	</link>

	<joint name="base_joint" type="revolute">
		<parent link="base_link" />
		<child link="mani_lid_link" />
		<axis xyz="0 0 1" />
		<limit effort="1000.0" lower="0.0" upper="3.1416" velocity="1.0" />
		<origin rpy="0 0 0" xyz="0 0 0.12" />
	</joint>

	<joint name="lid_joint" type="revolute">
		<parent link="mani_lid_link" />
		<child link="mani_arm01_link" />
		<axis xyz="0 0 1" />
		<limit effort="1000.0" lower="0.0" upper="3.1416" velocity="1.0" />
		<origin rpy="0 1.57 0" xyz="-0.007 0.025 0.083" />
	</joint>

	<joint name="arm01_joint" type="revolute">
		<parent link="mani_arm01_link" />
		<child link="mani_arm02_link" />
		<axis xyz="0 0 1" />
		<limit effort="1000.0" lower="0.0" upper="3.1416" velocity="1.0" />
		<origin rpy="0 3.1416 1" xyz="0.0335 0.238 0" />
	</joint>

	<joint name="arm02_joint" type="revolute">
		<parent link="mani_arm02_link" />
		<child link="mani_arm03_link" />
		<axis xyz="0 0 1" />
		<limit effort="1000.0" lower="0.0" upper="3.1416" velocity="1.0" />
		<origin rpy="1.57 0 0" xyz="-0.01 0.18 0.015" />
	</joint>

	<joint name="arm03_joint" type="revolute">
		<parent link="mani_arm03_link" />
		<child link="mani_gripper_base_link" />
		<axis xyz="0 0 1" />
		<limit effort="1000.0" lower="0.0" upper="3.1416" velocity="1.0" />
		<origin rpy="1.57 3.1416 0" xyz="0.01 -0.03 -0.055" />
	</joint>

	<joint name="gripper_base_joint" type="revolute">
		<parent link="mani_gripper_base_link" />
		<child link="mani_left_gear_link" />
		<axis xyz="0 0 1" />
		<limit effort="1000.0" lower="0.0" upper="1.3" velocity="1.0" />
		<origin rpy="1.57 0 0" xyz="0.08 0.028 -0.04" />
	</joint>

	<joint name="sub_gripper_base_joint" type="revolute">
		<parent link="mani_gripper_base_link" />
		<child link="mani_right_gear_link" />
		<mimic joint="gripper_base_joint" />
		<axis xyz="0 1 0" />
		<limit effort="1000.0" lower="0.0" upper="1.3" velocity="1.0" />
		<origin rpy="0 0 0" xyz="0.077 0.028 0.015" />
	</joint>

	<joint name="gear_support_joint" type="revolute">
		<parent link="mani_gripper_base_link" />
		<child link="mani_left_gear_support_link" />
		<mimic joint="gripper_base_joint" />
		<axis xyz="0 0 1" />
		<limit effort="1000.0" lower="0.0" upper="1.3" velocity="1.0" />
		<origin rpy="1.57 0 0" xyz="0.118 0.028 -0.021" />
	</joint>

	<joint name="sub_gear_support_joint" type="revolute">
		<parent link="mani_gripper_base_link" />
		<child link="mani_right_gear_support_link" />
		<mimic joint="gear_support_joint" />
		<axis xyz="0 1 0" />
		<limit effort="1000.0" lower="0.0" upper="1.3" velocity="1.0" />
		<origin rpy="0 0 0" xyz="0.118 0.028 -0.0005" />
	</joint>

	<joint name="gripper_joint" type="revolute">
		<parent link="mani_left_gear_link" />
		<child link="mani_left_gripper_link" />
		<mimic joint="gripper_base_joint" />
		<axis xyz="0 0 -1" />
		<limit effort="1000.0" lower="0.0" upper="1.3" velocity="1.0" />
		<origin rpy="0 0 0.42" xyz="0.015 -0.06 -0.01" />
	</joint>

	<joint name="sub_gripper_joint" type="revolute">
		<parent link="mani_right_gear_link" />
		<child link="mani_right_gripper_link" />
		<mimic joint="gripper_joint" />
		<axis xyz="0 0 1" />
		<limit effort="1000.0" lower="0.0" upper="1.3" velocity="1.0" />
		<origin rpy="1.57 0.32 0" xyz="0.023 0.01 0.057" />
	</joint>

	<material name="red">
		<color rgba="0.8 0 0 1" />
	</material>
	<material name="green">
		<color rgba="0 0.8 0 1" />
	</material>
	<material name="orange">
		<color rgba="0.57 0.17 0.0 1" />
	</material>
	<material name="white">
		<color rgba="0.8 0.8 0.8 1" />
	</material>
	<material name="black">
		<color rgba="0 0 0 1" />
	</material>
</robot>
